Workbook

Sheet 안내
A1: 재실행 결과 3인 판정 시트 (v1.1, 2026-09-27)
A3: 규칙 (ANALYSIS_PLAN 1절, 2026-09-02 고정): 생존 = 효과 방향 동일, 원 논문이 검정을 보고했으면 유의성 유지, 효과크기의 부호와 크기급 유지. 부분 생존 = 방향은 같으나 유의성 또는 크기급이 달라짐. 사망 = 방향이 뒤집히거나 핵심 주장이 성립하지 않음. 판정 불능 = 근거가 모자라 판단할 수 없음.
A4: 결론 수준 = 그 값이 뒷받침하던 논문의 문장이 지금도 성립하는가 (핵심 주장 성립 / 부분 성립 / 불성립 / 판단 불가).
A6: 채우는 칸은 노란색뿐입니다: 판정, 결론 수준, 메모. 다른 판정자와 상의하지 않고 채웁니다. 판정이 어려우면 메모에 이유를 적고 '판정 불능'을 고릅니다. 다수결과 일치 열은 수식이라 손대지 않습니다.
A7: 회색 열은 근거입니다. 원 논문 값, 재실행 값과 95% 구간, 문항 수, 파싱 실패 수, 비용 상한 부분집합 여부, 자동 가안. 자동 가안은 참고용이며 판정을 대신하지 않습니다. 자동 가안과 다르게 판정해도 됩니다. 그것이 이 작업의 목적입니다.
A8: 판단 기준은 값과 구간입니다. 원 논문 값이 재실행의 95% 구간 안이거나 차이가 2점 이내면 대체로 생존, 5점 이내면 부분 생존, 그 밖이면 사망으로 읽되, 지표의 성격(비율, 상관, 점수)과 논문이 그 값으로 무엇을 주장했는지를 함께 봅니다.
A10: TierA_claims: 저장소 기반 재실행 논문의 주장 95건. 근거 파일 열의 run_meta.json에 실행 조건과 관찰된 마찰이 있습니다. '사람 확인 항목'이 '예'인 논문은 harness/cards/HUMAN_CHECKS.md의 결정이 먼저 필요합니다.
A11: PromptLevel_blind: 프롬프트 수준 결과 343행(86편). 같은 논문의 행들은 사망 전 고정 모델 실행과 후속 모델 실행이 섞여 있고, 어느 것이 어느 조건인지는 조건 부호(A~E)로 가려져 있습니다. 조건을 추측하지 말고 행마다 값만 보고 판정합니다.
A12: 열쇠는 coding/judgment_key_v1.csv에 있으며 판정이 끝나기 전에는 열지 않습니다 (계획의 조건 가림 코딩).
A14: 예시 행 (형식만 보이기 위한 가상의 값입니다. 데이터 시트에는 들어 있지 않습니다):
A15: 번호 | B15: 논문 | C15: 원 논문 값 | D15: 재실행 값 | E15: 95% 구간 | F15: 판정 A | G15: 결론 수준 A | H15: 메모 A
A16: 0 | B16: (예시) 어떤 벤치마크 논문 | C16: 62 | D16: 60.5 | E16: [57.9, 63.1] | F16: 생존 | G16: 핵심 주장 성립 | H16: 구간 안, 방향 동일

Sheet TierA_claims
A1: 번호 | B1: 카드 | C1: 논문 | D1: 주장(지표) | E1: 원 논문 값 | F1: 재실행 값 | G1: 95% 구간 하한 | H1: 95% 구간 상한 | I1: 규칙(척도) | J1: 자동 판정(논문 단위 가안) | K1: 메모(자동) | L1: 근거 파일 | M1: 사람 확인 항목 | N1: 판정 A | O1: 판정 B | P1: 판정 C | Q1: 결론 수준 A | R1: 결론 수준 B | S1: 결론 수준 C | T1: 메모 A | U1: 메모 B | V1: 메모 C | W1: 다수결 | X1: 일치
A2: 1 | B2: T1 | C2: Benchmarking Large Language Models for Bio-Image Analysis Code Generation | D2: Bio-image code generation: pass@1 | E2: 0.47368421 | F2: 0.48070175 | G2: 0.374 | H2: 0.581 | I2: x100 | J2: 생존 (survived): point estimate inside original CI, pass@10 identical (42/57 tasks solved at least once in both); dated snapshot shows no detectable drift 17 months after the original run | L2: runs/T1/run_meta.json | W2: =IF(COUNTA(N2:P2)<3,"",IF(AND(N2=O2,O2=P2),N2,IF(N2=O2,N2,IF(N2=P2,N2,IF(O2=P2,O2,"판정 불능"))))) | X2: =IF(COUNTA(N2:P2)<3,"",IF(AND(N2=O2,O2=P2),"3/3",IF(OR(N2=O2,N2=P2,O2=P2),"2/3","0/3")))
A3: 2 | B3: W7171749161 | C3: Tag Questions and the Generational Reversal of Sycophancy Across 45 Language Models | D3: Tag Questions: tag effect on agreement | E3: -0.075 | F3: -0.10208333 | G3: -0.16458333 | H3: -0.052083333 | I3: x100 | J3: 생존 (survived) | K3: 90% interval as in the paper | L3: runs/W7171749161/run_meta.json | W3: =IF(COUNTA(N3:P3)<3,"",IF(AND(N3=O3,O3=P3),N3,IF(N3=O3,N3,IF(N3=P3,N3,IF(O3=P3,O3,"판정 불능"))))) | X3: =IF(COUNTA(N3:P3)<3,"",IF(AND(N3=O3,O3=P3),"3/3",IF(OR(N3=O3,N3=P3,O3=P3),"2/3","0/3")))
A4: 3 | B4: W7140135941 | C4: Knowing When to Abstain: Medical LLMs Under Clinical Uncertainty | D4: MedAbstain: accuracy, no abstain option | E4: 0.5404 | F4: 0.5418 | G4: 0.502 | H4: 0.58 | I4: x100 | J4: 부분 생존 (partial) | L4: runs/W7140135941/run_meta.json | W4: =IF(COUNTA(N4:P4)<3,"",IF(AND(N4=O4,O4=P4),N4,IF(N4=O4,N4,IF(N4=P4,N4,IF(O4=P4,O4,"판정 불능"))))) | X4: =IF(COUNTA(N4:P4)<3,"",IF(AND(N4=O4,O4=P4),"3/3",IF(OR(N4=O4,N4=P4,O4=P4),"2/3","0/3")))
A5: 4 | B5: W7140135941 | C5: Knowing When to Abstain: Medical LLMs Under Clinical Uncertainty | D5: MedAbstain: accuracy, abstain option | E5: 0.4099 | F5: 0.4113 | G5: 0.376 | H5: 0.445 | I5: x100 | J5: 부분 생존 (partial) | L5: runs/W7140135941/run_meta.json | W5: =IF(COUNTA(N5:P5)<3,"",IF(AND(N5=O5,O5=P5),N5,IF(N5=O5,N5,IF(N5=P5,N5,IF(O5=P5,O5,"판정 불능"))))) | X5: =IF(COUNTA(N5:P5)<3,"",IF(AND(N5=O5,O5=P5),"3/3",IF(OR(N5=O5,N5=P5,O5=P5),"2/3","0/3")))
A6: 5 | B6: W7140135941 | C6: Knowing When to Abstain: Medical LLMs Under Clinical Uncertainty | D6: MedAbstain: accuracy, distractor + abstain | E6: 0.3688 | F6: 0.3603 | G6: 0.325 | H6: 0.396 | I6: x100 | J6: 부분 생존 (partial) | L6: runs/W7140135941/run_meta.json | W6: =IF(COUNTA(N6:P6)<3,"",IF(AND(N6=O6,O6=P6),N6,IF(N6=O6,N6,IF(N6=P6,N6,IF(O6=P6,O6,"판정 불능"))))) | X6: =IF(COUNTA(N6:P6)<3,"",IF(AND(N6=O6,O6=P6),"3/3",IF(OR(N6=O6,N6=P6,O6=P6),"2/3","0/3")))
A7: 6 | B7: W7140135941 | C7: Knowing When to Abstain: Medical LLMs Under Clinical Uncertainty | D7: MedAbstain: abstention rate (abstain option) | E7: 0 | F7: 0.025 | I7: x100 | J7: 부분 생존 (partial) | L7: runs/W7140135941/run_meta.json | W7: =IF(COUNTA(N7:P7)<3,"",IF(AND(N7=O7,O7=P7),N7,IF(N7=O7,N7,IF(N7=P7,N7,IF(O7=P7,O7,"판정 불능"))))) | X7: =IF(COUNTA(N7:P7)<3,"",IF(AND(N7=O7,O7=P7),"3/3",IF(OR(N7=O7,N7=P7,O7=P7),"2/3","0/3")))
A8: 7 | B8: W4362598103 | C8: Accuracy and Political Bias of News Source Credibility Ratings by Large Language Models | D8: News credibility: Spearman rho x100 vs expert ratings | E8: 0.62418425 | F8: 0.62940061 | G8: 0.60971275 | H8: 0.64825062 | I8: x100 | J8: 부분 생존 (partial) | L8: runs/W4362598103/run_meta.json | W8: =IF(COUNTA(N8:P8)<3,"",IF(AND(N8=O8,O8=P8),N8,IF(N8=O8,N8,IF(N8=P8,N8,IF(O8=P8,O8,"판정 불능"))))) | X8: =IF(COUNTA(N8:P8)<3,"",IF(AND(N8=O8,O8=P8),"3/3",IF(OR(N8=O8,N8=P8,O8=P8),"2/3","0/3")))
A9: 8 | B9: W4362598103 | C9: Accuracy and Political Bias of News Source Credibility Ratings by Large Language Models | D9: News credibility: refusal share | E9: 0.41220258 | F9: 0.35429407 | I9: x100 | J9: 부분 생존 (partial) | L9: runs/W4362598103/run_meta.json | W9: =IF(COUNTA(N9:P9)<3,"",IF(AND(N9=O9,O9=P9),N9,IF(N9=O9,N9,IF(N9=P9,N9,IF(O9=P9,O9,"판정 불능"))))) | X9: =IF(COUNTA(N9:P9)<3,"",IF(AND(N9=O9,O9=P9),"3/3",IF(OR(N9=O9,N9=P9,O9=P9),"2/3","0/3")))
A10: 9 | B10: W7144391134 | C10: In-Context Molecular Property Prediction with LLMs: A Blinding Study on Memorization and K | D10: BlindingLLMs: Pearson r x100, 1000-shot | E10: 75.6 | F10: 76.6 | G10: 69.2 | H10: 82.8 | I10: pts | J10: 생존 (survived) | L10: runs/W7144391134/run_meta.json | W10: =IF(COUNTA(N10:P10)<3,"",IF(AND(N10=O10,O10=P10),N10,IF(N10=O10,N10,IF(N10=P10,N10,IF(O10=P10,O10,"판정 불능"))))) | X10: =IF(COUNTA(N10:P10)<3,"",IF(AND(N10=O10,O10=P10),"3/3",IF(OR(N10=O10,N10=P10,O10=P10),"2/3","0/3")))
A11: 10 | B11: W7144391134 | C11: In-Context Molecular Property Prediction with LLMs: A Blinding Study on Memorization and K | D11: BlindingLLMs: Pearson r x100, 60-shot | E11: 42.9 | F11: 37.6 | G11: 21.7 | H11: 52.2 | I11: pts | J11: 생존 (survived) | L11: runs/W7144391134/run_meta.json | W11: =IF(COUNTA(N11:P11)<3,"",IF(AND(N11=O11,O11=P11),N11,IF(N11=O11,N11,IF(N11=P11,N11,IF(O11=P11,O11,"판정 불능"))))) | X11: =IF(COUNTA(N11:P11)<3,"",IF(AND(N11=O11,O11=P11),"3/3",IF(OR(N11=O11,N11=P11,O11=P11),"2/3","0/3")))
A12: 11 | B12: W7144391134 | C12: In-Context Molecular Property Prediction with LLMs: A Blinding Study on Memorization and K | D12: BlindingLLMs: Pearson r, 0-shot | E12: 0.407 | F12: 0.406 | I12: x100 | J12: 생존 (survived) | L12: runs/W7144391134/run_meta.json | W12: =IF(COUNTA(N12:P12)<3,"",IF(AND(N12=O12,O12=P12),N12,IF(N12=O12,N12,IF(N12=P12,N12,IF(O12=P12,O12,"판정 불능"))))) | X12: =IF(COUNTA(N12:P12)<3,"",IF(AND(N12=O12,O12=P12),"3/3",IF(OR(N12=O12,N12=P12,O12=P12),"2/3","0/3")))
A13: 12 | B13: W4402565126 | C13: Cultural bias and cultural alignment of large language models | D13: Cultural bias: distance reduction (107 countries) | E13: 0.93410473 | F13: 0.93306983 | G13: 0.71092737 | H13: 1.1404791 | I13: other:distance | J13: 생존 (survived) | L13: runs/W4402565126/run_meta.json | W13: =IF(COUNTA(N13:P13)<3,"",IF(AND(N13=O13,O13=P13),N13,IF(N13=O13,N13,IF(N13=P13,N13,IF(O13=P13,O13,"판정 불능"))))) | X13: =IF(COUNTA(N13:P13)<3,"",IF(AND(N13=O13,O13=P13),"3/3",IF(OR(N13=O13,N13=P13,O13=P13),"2/3","0/3")))
A14: 13 | B14: W4402565126 | C14: Cultural bias and cultural alignment of large language models | D14: Cultural bias: share of countries improved | E14: 0.81308411 | F14: 0.78504673 | I14: x100 | J14: 생존 (survived) | L14: runs/W4402565126/run_meta.json | W14: =IF(COUNTA(N14:P14)<3,"",IF(AND(N14=O14,O14=P14),N14,IF(N14=O14,N14,IF(N14=P14,N14,IF(O14=P14,O14,"판정 불능"))))) | X14: =IF(COUNTA(N14:P14)<3,"",IF(AND(N14=O14,O14=P14),"3/3",IF(OR(N14=O14,N14=P14,O14=P14),"2/3","0/3")))
A15: 14 | B15: W4412887943 | C15: MEDEC: A Benchmark for Medical Error Detection and Correction in Clinical Notes | D15: MEDEC: error flag accuracy (vs Table 2 GPT-4o) | E15: 0.6584 | F15: 0.5611 | G15: 0.5215 | H15: 0.5997 | I15: x100 | J15: 부분 생존 (partial) [subset: MS 597/925] | K15: MS subset 597/925; GPT-4o-mini row 0.6086 | L15: runs/W4412887943/run_meta.json | W15: =IF(COUNTA(N15:P15)<3,"",IF(AND(N15=O15,O15=P15),N15,IF(N15=O15,N15,IF(N15=P15,N15,IF(O15=P15,O15,"판정 불능"))))) | X15: =IF(COUNTA(N15:P15)<3,"",IF(AND(N15=O15,O15=P15),"3/3",IF(OR(N15=O15,N15=P15,O15=P15),"2/3","0/3")))
A16: 15 | B16: W4412887943 | C16: MEDEC: A Benchmark for Medical Error Detection and Correction in Clinical Notes | D16: MEDEC: error sentence accuracy (vs Table 2 GPT-4o) | E16: 0.5665 | F16: 0.4606 | G16: 0.4204 | H16: 0.5003 | I16: x100 | J16: 부분 생존 (partial) [subset: MS 597/925] | K16: MS subset 597/925; GPT-4o-mini row 0.4757 | L16: runs/W4412887943/run_meta.json | W16: =IF(COUNTA(N16:P16)<3,"",IF(AND(N16=O16,O16=P16),N16,IF(N16=O16,N16,IF(N16=P16,N16,IF(O16=P16,O16,"판정 불능"))))) | X16: =IF(COUNTA(N16:P16)<3,"",IF(AND(N16=O16,O16=P16),"3/3",IF(OR(N16=O16,N16=P16,O16=P16),"2/3","0/3")))
A17: 16 | B17: W4412945732 | C17: Pattern Recognition or Medical Knowledge? The Problem with Multiple-Choice Questions in Me | D17: Glianorex gpt-4o: accuracy, en gpt | E17: 0.74 | F17: 0.7576 | G17: 0.7058 | H17: 0.8068 | I17: x100 | J17: 생존 (survived) | L17: runs/W4412945732/run_meta.json | W17: =IF(COUNTA(N17:P17)<3,"",IF(AND(N17=O17,O17=P17),N17,IF(N17=O17,N17,IF(N17=P17,N17,IF(O17=P17,O17,"판정 불능"))))) | X17: =IF(COUNTA(N17:P17)<3,"",IF(AND(N17=O17,O17=P17),"3/3",IF(OR(N17=O17,N17=P17,O17=P17),"2/3","0/3")))
A18: 17 | B18: W4412945732 | C18: Pattern Recognition or Medical Knowledge? The Problem with Multiple-Choice Questions in Me | D18: Glianorex gpt-4o: accuracy, en claude | E18: 0.72 | F18: 0.7232 | G18: 0.6637 | H18: 0.7812 | I18: x100 | J18: 생존 (survived) | L18: runs/W4412945732/run_meta.json | W18: =IF(COUNTA(N18:P18)<3,"",IF(AND(N18=O18,O18=P18),N18,IF(N18=O18,N18,IF(N18=P18,N18,IF(O18=P18,O18,"판정 불능"))))) | X18: =IF(COUNTA(N18:P18)<3,"",IF(AND(N18=O18,O18=P18),"3/3",IF(OR(N18=O18,N18=P18,O18=P18),"2/3","0/3")))
A19: 18 | B19: W4412945732 | C19: Pattern Recognition or Medical Knowledge? The Problem with Multiple-Choice Questions in Me | D19: Glianorex gpt-4o: accuracy, fr gpt | E19: 0.69 | F19: 0.7083 | G19: 0.649 | H19: 0.7551 | I19: x100 | J19: 생존 (survived) | L19: runs/W4412945732/run_meta.json | W19: =IF(COUNTA(N19:P19)<3,"",IF(AND(N19=O19,O19=P19),N19,IF(N19=O19,N19,IF(N19=P19,N19,IF(O19=P19,O19,"판정 불능"))))) | X19: =IF(COUNTA(N19:P19)<3,"",IF(AND(N19=O19,O19=P19),"3/3",IF(OR(N19=O19,N19=P19,O19=P19),"2/3","0/3")))
A20: 19 | B20: W4412945732 | C20: Pattern Recognition or Medical Knowledge? The Problem with Multiple-Choice Questions in Me | D20: Glianorex gpt-4o: accuracy, fr claude | E20: 0.71 | F20: 0.7188 | G20: 0.6592 | H20: 0.7769 | I20: x100 | J20: 생존 (survived) | L20: runs/W4412945732/run_meta.json | W20: =IF(COUNTA(N20:P20)<3,"",IF(AND(N20=O20,O20=P20),N20,IF(N20=O20,N20,IF(N20=P20,N20,IF(O20=P20,O20,"판정 불능"))))) | X20: =IF(COUNTA(N20:P20)<3,"",IF(AND(N20=O20,O20=P20),"3/3",IF(OR(N20=O20,N20=P20,O20=P20),"2/3","0/3")))
A21: 20 | B21: W4412945732 | C21: Pattern Recognition or Medical Knowledge? The Problem with Multiple-Choice Questions in Me | D21: Glianorex gpt-4-turbo: accuracy, en gpt | E21: 0.65 | F21: 0.6591 | G21: 0.6048 | H21: 0.7172 | I21: x100 | J21: 생존 (survived) | L21: runs/W4412945732/run_meta.json | W21: =IF(COUNTA(N21:P21)<3,"",IF(AND(N21=O21,O21=P21),N21,IF(N21=O21,N21,IF(N21=P21,N21,IF(O21=P21,O21,"판정 불능"))))) | X21: =IF(COUNTA(N21:P21)<3,"",IF(AND(N21=O21,O21=P21),"3/3",IF(OR(N21=O21,N21=P21,O21=P21),"2/3","0/3")))
A22: 21 | B22: W4412945732 | C22: Pattern Recognition or Medical Knowledge? The Problem with Multiple-Choice Questions in Me | D22: Glianorex gpt-4-turbo: accuracy, en claude | E22: 0.69 | F22: 0.692 | G22: 0.6279 | H22: 0.7485 | I22: x100 | J22: 생존 (survived) | L22: runs/W4412945732/run_meta.json | W22: =IF(COUNTA(N22:P22)<3,"",IF(AND(N22=O22,O22=P22),N22,IF(N22=O22,N22,IF(N22=P22,N22,IF(O22=P22,O22,"판정 불능"))))) | X22: =IF(COUNTA(N22:P22)<3,"",IF(AND(N22=O22,O22=P22),"3/3",IF(OR(N22=O22,N22=P22,O22=P22),"2/3","0/3")))
A23: 22 | B23: W4412945732 | C23: Pattern Recognition or Medical Knowledge? The Problem with Multiple-Choice Questions in Me | D23: Glianorex gpt-4-turbo: accuracy, fr gpt | E23: 0.68 | F23: 0.6591 | G23: 0.596 | H23: 0.7121 | I23: x100 | J23: 생존 (survived) | L23: runs/W4412945732/run_meta.json | W23: =IF(COUNTA(N23:P23)<3,"",IF(AND(N23=O23,O23=P23),N23,IF(N23=O23,N23,IF(N23=P23,N23,IF(O23=P23,O23,"판정 불능"))))) | X23: =IF(COUNTA(N23:P23)<3,"",IF(AND(N23=O23,O23=P23),"3/3",IF(OR(N23=O23,N23=P23,O23=P23),"2/3","0/3")))
A24: 23 | B24: W4412945732 | C24: Pattern Recognition or Medical Knowledge? The Problem with Multiple-Choice Questions in Me | D24: Glianorex gpt-4-turbo: accuracy, fr claude | E24: 0.68 | F24: 0.6741 | G24: 0.6131 | H24: 0.7336 | I24: x100 | J24: 생존 (survived) | L24: runs/W4412945732/run_meta.json | W24: =IF(COUNTA(N24:P24)<3,"",IF(AND(N24=O24,O24=P24),N24,IF(N24=O24,N24,IF(N24=P24,N24,IF(O24=P24,O24,"판정 불능"))))) | X24: =IF(COUNTA(N24:P24)<3,"",IF(AND(N24=O24,O24=P24),"3/3",IF(OR(N24=O24,N24=P24,O24=P24),"2/3","0/3")))
A25: 24 | B25: W4396768794 | C25: Assessing DxGPT: Diagnosing Rare Diseases with Various Large Language Models | D25: DxGPT: strict top-1 (new vs archived diagnoses, same judge) | E25: 58.5 | F25: 57 | G25: 51 | H25: 64 | I25: pts | J25: 생존 (survival) | K25: judge-matched comparison; Table 3 with the original judge 54.0 | L25: runs/W4396768794/run_meta.json | W25: =IF(COUNTA(N25:P25)<3,"",IF(AND(N25=O25,O25=P25),N25,IF(N25=O25,N25,IF(N25=P25,N25,IF(O25=P25,O25,"판정 불능"))))) | X25: =IF(COUNTA(N25:P25)<3,"",IF(AND(N25=O25,O25=P25),"3/3",IF(OR(N25=O25,N25=P25,O25=P25),"2/3","0/3")))
A26: 25 | B26: W4396768794 | C26: Assessing DxGPT: Diagnosing Rare Diseases with Various Large Language Models | D26: DxGPT: top-5 (new vs archived diagnoses, same judge) | E26: 69 | F26: 69.5 | G26: 63.4875 | H26: 76 | I26: pts | J26: 생존 (survival) | L26: runs/W4396768794/run_meta.json | W26: =IF(COUNTA(N26:P26)<3,"",IF(AND(N26=O26,O26=P26),N26,IF(N26=O26,N26,IF(N26=P26,N26,IF(O26=P26,O26,"판정 불능"))))) | X26: =IF(COUNTA(N26:P26)<3,"",IF(AND(N26=O26,O26=P26),"3/3",IF(OR(N26=O26,N26=P26,O26=P26),"2/3","0/3")))
A27: 26 | B27: W4405408496 | C27: The Impact of Temperature on Extracting Information From Clinical Trial Publications Using | D27: Temperature study gpt-4o: formatted numeric answers, T=0.00 | E27: 98.7 | F27: 98.393574 | G27: 97.289157 | H27: 98.995984 | I27: pts | J27: 생존 (survived) | K27: median over 3 pass(es) | L27: runs/W4405408496/run_meta.json | W27: =IF(COUNTA(N27:P27)<3,"",IF(AND(N27=O27,O27=P27),N27,IF(N27=O27,N27,IF(N27=P27,N27,IF(O27=P27,O27,"판정 불능"))))) | X27: =IF(COUNTA(N27:P27)<3,"",IF(AND(N27=O27,O27=P27),"3/3",IF(OR(N27=O27,N27=P27,O27=P27),"2/3","0/3")))
A28: 27 | B28: W4405408496 | C28: The Impact of Temperature on Extracting Information From Clinical Trial Publications Using | D28: Temperature study gpt-4o: formatted numeric answers, T=1.50 | E28: 98.7 | F28: 97.891566 | G28: 96.985442 | H28: 98.694779 | I28: pts | J28: 생존 (survived) | K28: median over 1 pass(es) | L28: runs/W4405408496/run_meta.json | W28: =IF(COUNTA(N28:P28)<3,"",IF(AND(N28=O28,O28=P28),N28,IF(N28=O28,N28,IF(N28=P28,N28,IF(O28=P28,O28,"판정 불능"))))) | X28: =IF(COUNTA(N28:P28)<3,"",IF(AND(N28=O28,O28=P28),"3/3",IF(OR(N28=O28,N28=P28,O28=P28),"2/3","0/3")))
A29: 28 | B29: W4405408496 | C29: The Impact of Temperature on Extracting Information From Clinical Trial Publications Using | D29: Temperature study gpt-4o: formatted numeric answers, T=1.75 | E29: 95.6 | F29: 96.285141 | G29: 95.080321 | H29: 97.389558 | I29: pts | J29: 생존 (survived) | K29: median over 1 pass(es) | L29: runs/W4405408496/run_meta.json | W29: =IF(COUNTA(N29:P29)<3,"",IF(AND(N29=O29,O29=P29),N29,IF(N29=O29,N29,IF(N29=P29,N29,IF(O29=P29,O29,"판정 불능"))))) | X29: =IF(COUNTA(N29:P29)<3,"",IF(AND(N29=O29,O29=P29),"3/3",IF(OR(N29=O29,N29=P29,O29=P29),"2/3","0/3")))
A30: 29 | B30: W4405408496 | C30: The Impact of Temperature on Extracting Information From Clinical Trial Publications Using | D30: Temperature study gpt-4o: formatted numeric answers, T=2.00 | E30: 89.2 | F30: 86.84739 | G30: 84.738956 | H30: 88.855422 | I30: pts | J30: 생존 (survived) | K30: median over 3 pass(es) | L30: runs/W4405408496/run_meta.json | W30: =IF(COUNTA(N30:P30)<3,"",IF(AND(N30=O30,O30=P30),N30,IF(N30=O30,N30,IF(N30=P30,N30,IF(O30=P30,O30,"판정 불능"))))) | X30: =IF(COUNTA(N30:P30)<3,"",IF(AND(N30=O30,O30=P30),"3/3",IF(OR(N30=O30,N30=P30,O30=P30),"2/3","0/3")))
A31: 30 | B31: W4405408496 | C31: The Impact of Temperature on Extracting Information From Clinical Trial Publications Using | D31: Temperature study gpt-4o: MAPE of formatted answers, T=0.00 | E31: 1.7 | F31: 1.4012268 | G31: 0.84360383 | H31: 2.1007196 | I31: pts | J31: 생존 (survived) | L31: runs/W4405408496/run_meta.json | W31: =IF(COUNTA(N31:P31)<3,"",IF(AND(N31=O31,O31=P31),N31,IF(N31=O31,N31,IF(N31=P31,N31,IF(O31=P31,O31,"판정 불능"))))) | X31: =IF(COUNTA(N31:P31)<3,"",IF(AND(N31=O31,O31=P31),"3/3",IF(OR(N31=O31,N31=P31,O31=P31),"2/3","0/3")))
A32: 31 | B32: W4405408496 | C32: The Impact of Temperature on Extracting Information From Clinical Trial Publications Using | D32: Temperature study gpt-4o: MAPE of formatted answers, T=2.00 | E32: 1 | F32: 1.8047491 | G32: 0.89754953 | H32: 4.2214396 | I32: pts | J32: 생존 (survived) | L32: runs/W4405408496/run_meta.json | W32: =IF(COUNTA(N32:P32)<3,"",IF(AND(N32=O32,O32=P32),N32,IF(N32=O32,N32,IF(N32=P32,N32,IF(O32=P32,O32,"판정 불능"))))) | X32: =IF(COUNTA(N32:P32)<3,"",IF(AND(N32=O32,O32=P32),"3/3",IF(OR(N32=O32,N32=P32,O32=P32),"2/3","0/3")))
A33: 32 | B33: W4405408496 | C33: The Impact of Temperature on Extracting Information From Clinical Trial Publications Using | D33: Temperature study gpt-4o-mini: formatted numeric answers, T=2.00 | E33: 90.2 | F33: 90.160643 | G33: 88.253012 | H33: 91.86998 | I33: pts | J33: 생존 (survived) | L33: runs/W4405408496/run_meta.json | W33: =IF(COUNTA(N33:P33)<3,"",IF(AND(N33=O33,O33=P33),N33,IF(N33=O33,N33,IF(N33=P33,N33,IF(O33=P33,O33,"판정 불능"))))) | X33: =IF(COUNTA(N33:P33)<3,"",IF(AND(N33=O33,O33=P33),"3/3",IF(OR(N33=O33,N33=P33,O33=P33),"2/3","0/3")))
A34: 33 | B34: W4400435289 | C34: Me, Myself, and AI: The Situational Awareness Dataset (SAD) for LLMs | D34: SAD-mini facts_human_defaults: accuracy | E34: 0.75 | F34: 0.7975 | G34: 0.774 | H34: 0.8199 | I34: x100 | J34: 생존 (survived) | K34: substitute snapshot gpt-4o-2024-05-13 | L34: runs/W4400435289/run_meta.json | W34: =IF(COUNTA(N34:P34)<3,"",IF(AND(N34=O34,O34=P34),N34,IF(N34=O34,N34,IF(N34=P34,N34,IF(O34=P34,O34,"판정 불능"))))) | X34: =IF(COUNTA(N34:P34)<3,"",IF(AND(N34=O34,O34=P34),"3/3",IF(OR(N34=O34,N34=P34,O34=P34),"2/3","0/3")))
A35: 34 | B35: W4400435289 | C35: Me, Myself, and AI: The Situational Awareness Dataset (SAD) for LLMs | D35: SAD-mini facts_llms: accuracy | E35: 0.89156627 | F35: 0.87550201 | G35: 0.8353 | H35: 0.9157 | I35: x100 | J35: 생존 (survived) | K35: substitute snapshot gpt-4o-2024-05-13 | L35: runs/W4400435289/run_meta.json | W35: =IF(COUNTA(N35:P35)<3,"",IF(AND(N35=O35,O35=P35),N35,IF(N35=O35,N35,IF(N35=P35,N35,IF(O35=P35,O35,"판정 불능"))))) | X35: =IF(COUNTA(N35:P35)<3,"",IF(AND(N35=O35,O35=P35),"3/3",IF(OR(N35=O35,N35=P35,O35=P35),"2/3","0/3")))
A36: 35 | B36: W4400435289 | C36: Me, Myself, and AI: The Situational Awareness Dataset (SAD) for LLMs | D36: SAD-mini influence: accuracy | E36: 0.678125 | F36: 0.703125 | G36: 0.6497 | H36: 0.7565 | I36: x100 | J36: 생존 (survived) | K36: substitute snapshot gpt-4o-2024-05-13 | L36: runs/W4400435289/run_meta.json | W36: =IF(COUNTA(N36:P36)<3,"",IF(AND(N36=O36,O36=P36),N36,IF(N36=O36,N36,IF(N36=P36,N36,IF(O36=P36,O36,"판정 불능"))))) | X36: =IF(COUNTA(N36:P36)<3,"",IF(AND(N36=O36,O36=P36),"3/3",IF(OR(N36=O36,N36=P36,O36=P36),"2/3","0/3")))
A37: 36 | B37: W4400435289 | C37: Me, Myself, and AI: The Situational Awareness Dataset (SAD) for LLMs | D37: SAD-mini stages_full: accuracy | E37: 0.3375 | F37: 0.33875 | G37: 0.305 | H37: 0.37 | I37: x100 | J37: 생존 (survived) | K37: substitute snapshot gpt-4o-2024-05-13 | L37: runs/W4400435289/run_meta.json | W37: =IF(COUNTA(N37:P37)<3,"",IF(AND(N37=O37,O37=P37),N37,IF(N37=O37,N37,IF(N37=P37,N37,IF(O37=P37,O37,"판정 불능"))))) | X37: =IF(COUNTA(N37:P37)<3,"",IF(AND(N37=O37,O37=P37),"3/3",IF(OR(N37=O37,N37=P37,O37=P37),"2/3","0/3")))
A38: 37 | B38: W4400435289 | C38: Me, Myself, and AI: The Situational Awareness Dataset (SAD) for LLMs | D38: SAD-mini stages_oversight: accuracy | E38: 0.4575 | F38: 0.4575 | G38: 0.4067 | H38: 0.4983 | I38: x100 | J38: 생존 (survived) | K38: substitute snapshot gpt-4o-2024-05-13 | L38: runs/W4400435289/run_meta.json | W38: =IF(COUNTA(N38:P38)<3,"",IF(AND(N38=O38,O38=P38),N38,IF(N38=O38,N38,IF(N38=P38,N38,IF(O38=P38,O38,"판정 불능"))))) | X38: =IF(COUNTA(N38:P38)<3,"",IF(AND(N38=O38,O38=P38),"3/3",IF(OR(N38=O38,N38=P38,O38=P38),"2/3","0/3")))
A39: 38 | B39: W4400435289 | C39: Me, Myself, and AI: The Situational Awareness Dataset (SAD) for LLMs | D39: SAD-mini SAD-mini/paper_unweighted: accuracy | E39: 0.623 | F39: 0.6319754 | G39: 0.614 | H39: 0.6509 | I39: x100 | J39: 생존 (survived) | K39: substitute snapshot gpt-4o-2024-05-13 | L39: runs/W4400435289/run_meta.json | W39: =IF(COUNTA(N39:P39)<3,"",IF(AND(N39=O39,O39=P39),N39,IF(N39=O39,N39,IF(N39=P39,N39,IF(O39=P39,O39,"판정 불능"))))) | X39: =IF(COUNTA(N39:P39)<3,"",IF(AND(N39=O39,O39=P39),"3/3",IF(OR(N39=O39,N39=P39,O39=P39),"2/3","0/3")))
A40: 39 | B40: W4400435289 | C40: Me, Myself, and AI: The Situational Awareness Dataset (SAD) for LLMs | D40: SAD-mini SAD-mini/repo_weighted: accuracy | E40: 0.59440663 | F40: 0.6053002 | G40: 0.58 | H40: 0.6332 | I40: x100 | J40: 생존 (survived) | K40: substitute snapshot gpt-4o-2024-05-13 | L40: runs/W4400435289/run_meta.json | W40: =IF(COUNTA(N40:P40)<3,"",IF(AND(N40=O40,O40=P40),N40,IF(N40=O40,N40,IF(N40=P40,N40,IF(O40=P40,O40,"판정 불능"))))) | X40: =IF(COUNTA(N40:P40)<3,"",IF(AND(N40=O40,O40=P40),"3/3",IF(OR(N40=O40,N40=P40,O40=P40),"2/3","0/3")))
...

Sheet PromptLevel_blind
A1: 번호 | B1: 논문 ID | C1: 논문 | D1: 지표 | E1: 원 논문 값 | F1: 조건 부호 | G1: 재실행 값 | H1: 95% 구간 하한 | I1: 95% 구간 상한 | J1: 문항 수 | K1: 파싱 실패 수 | L1: 비용 상한 부분집합 | M1: 자동 가안(값 수준) | N1: 저정밀(구간 반폭>10점) | O1: 판정 A | P1: 판정 B | Q1: 판정 C | R1: 결론 수준 A | S1: 결론 수준 B | T1: 결론 수준 C | U1: 메모 A | V1: 메모 B | W1: 메모 C | X1: 다수결 | Y1: 일치
A2: 1 | B2: W4399317891 | C2: OR-Bench: An Over-Refusal Benchmark for Large Langua | D2: custom | E2: 12.7 | F2: A | G2: 14.25031 | H2: 10.780669 | I2: 19.330855 | J2: 269 | K2: 0 | L2: 예 | M2: 재현 | X2: =IF(COUNTA(O2:Q2)<3,"",IF(AND(O2=P2,P2=Q2),O2,IF(O2=P2,O2,IF(O2=Q2,O2,IF(P2=Q2,P2,"판정 불능"))))) | Y2: =IF(COUNTA(O2:Q2)<3,"",IF(AND(O2=P2,P2=Q2),"3/3",IF(OR(O2=P2,O2=Q2,P2=Q2),"2/3","0/3")))
A3: 2 | B3: W4399317891 | C3: OR-Bench: An Over-Refusal Benchmark for Large Langua | D3: custom | E3: 12.7 | F3: B | G3: 15.986 | H3: 11.905 | I3: 20.408 | J3: 294 | K3: 0 | L3: 예 | M3: 재현 | X3: =IF(COUNTA(O3:Q3)<3,"",IF(AND(O3=P3,P3=Q3),O3,IF(O3=P3,O3,IF(O3=Q3,O3,IF(P3=Q3,P3,"판정 불능"))))) | Y3: =IF(COUNTA(O3:Q3)<3,"",IF(AND(O3=P3,P3=Q3),"3/3",IF(OR(O3=P3,O3=Q3,P3=Q3),"2/3","0/3")))
A4: 3 | B4: W4399317891 | C4: OR-Bench: An Over-Refusal Benchmark for Large Langua | D4: custom | E4: 12.7 | F4: C | G4: 26.478 | H4: 22.108 | I4: 30.848 | J4: 931 | K4: 0 | L4: 예 | M4: 편차 | X4: =IF(COUNTA(O4:Q4)<3,"",IF(AND(O4=P4,P4=Q4),O4,IF(O4=P4,O4,IF(O4=Q4,O4,IF(P4=Q4,P4,"판정 불능"))))) | Y4: =IF(COUNTA(O4:Q4)<3,"",IF(AND(O4=P4,P4=Q4),"3/3",IF(OR(O4=P4,O4=Q4,P4=Q4),"2/3","0/3")))
A5: 4 | B5: W4399404161 | C5: MMLU-Pro: A More Robust and Challenging Multi-Task L | D5: accuracy | E5: 63.7 | F5: A | G5: 67.978208 | H5: 65.738499 | I5: 70.217918 | J5: 1652 | K5: 0 | L5: 예 | M5: 근접 | X5: =IF(COUNTA(O5:Q5)<3,"",IF(AND(O5=P5,P5=Q5),O5,IF(O5=P5,O5,IF(O5=Q5,O5,IF(P5=Q5,P5,"판정 불능"))))) | Y5: =IF(COUNTA(O5:Q5)<3,"",IF(AND(O5=P5,P5=Q5),"3/3",IF(OR(O5=P5,O5=Q5,P5=Q5),"2/3","0/3")))
A6: 5 | B6: W4399911093 | C6: Leveraging Large Language Models to Measure Gender R | D6: custom | E6: 90.24 | F6: A | G6: 90.873133 | H6: 89.13055 | I6: 92.928273 | J6: 100 | K6: 0 | M6: 재현 | X6: =IF(COUNTA(O6:Q6)<3,"",IF(AND(O6=P6,P6=Q6),O6,IF(O6=P6,O6,IF(O6=Q6,O6,IF(P6=Q6,P6,"판정 불능"))))) | Y6: =IF(COUNTA(O6:Q6)<3,"",IF(AND(O6=P6,P6=Q6),"3/3",IF(OR(O6=P6,O6=Q6,P6=Q6),"2/3","0/3")))
A7: 6 | B7: W4399911093 | C7: Leveraging Large Language Models to Measure Gender R | D7: custom | E7: 90.24 | F7: B | G7: 84.16 | H7: 80.749 | I7: 87.219 | J7: 100 | K7: 0 | M7: 편차 | X7: =IF(COUNTA(O7:Q7)<3,"",IF(AND(O7=P7,P7=Q7),O7,IF(O7=P7,O7,IF(O7=Q7,O7,IF(P7=Q7,P7,"판정 불능"))))) | Y7: =IF(COUNTA(O7:Q7)<3,"",IF(AND(O7=P7,P7=Q7),"3/3",IF(OR(O7=P7,O7=Q7,P7=Q7),"2/3","0/3")))
A8: 7 | B8: W4399911093 | C8: Leveraging Large Language Models to Measure Gender R | D8: custom | E8: 90.24 | F8: C | G8: 95.259 | H8: 93.907 | I8: 96.563 | J8: 100 | K8: 0 | M8: 편차 | X8: =IF(COUNTA(O8:Q8)<3,"",IF(AND(O8=P8,P8=Q8),O8,IF(O8=P8,O8,IF(O8=Q8,O8,IF(P8=Q8,P8,"판정 불능"))))) | Y8: =IF(COUNTA(O8:Q8)<3,"",IF(AND(O8=P8,P8=Q8),"3/3",IF(OR(O8=P8,O8=Q8,P8=Q8),"2/3","0/3")))
A9: 8 | B9: W4399911093 | C9: Leveraging Large Language Models to Measure Gender R | D9: custom | E9: 90.24 | F9: D | G9: 80.309 | H9: 75.78 | I9: 84.589 | J9: 100 | K9: 0 | M9: 편차 | X9: =IF(COUNTA(O9:Q9)<3,"",IF(AND(O9=P9,P9=Q9),O9,IF(O9=P9,O9,IF(O9=Q9,O9,IF(P9=Q9,P9,"판정 불능"))))) | Y9: =IF(COUNTA(O9:Q9)<3,"",IF(AND(O9=P9,P9=Q9),"3/3",IF(OR(O9=P9,O9=Q9,P9=Q9),"2/3","0/3")))
A10: 9 | B10: W4399911093 | C10: Leveraging Large Language Models to Measure Gender R | D10: custom | E10: 90.24 | F10: E | G10: 94.509 | H10: 93.157 | I10: 95.85 | J10: 100 | K10: 0 | M10: 근접 | X10: =IF(COUNTA(O10:Q10)<3,"",IF(AND(O10=P10,P10=Q10),O10,IF(O10=P10,O10,IF(O10=Q10,O10,IF(P10=Q10,P10,"판정 불능"))))) | Y10: =IF(COUNTA(O10:Q10)<3,"",IF(AND(O10=P10,P10=Q10),"3/3",IF(OR(O10=P10,O10=Q10,P10=Q10),"2/3","0/3")))
A11: 10 | B11: W4399911213 | C11: WikiContradict: A Benchmark for Evaluating LLMs on R | D11: accuracy | E11: 86.7 | F11: A | G11: 84.583 | H11: 80 | I11: 89.167 | J11: 240 | K11: 0 | M11: 재현 | X11: =IF(COUNTA(O11:Q11)<3,"",IF(AND(O11=P11,P11=Q11),O11,IF(O11=P11,O11,IF(O11=Q11,O11,IF(P11=Q11,P11,"판정 불능"))))) | Y11: =IF(COUNTA(O11:Q11)<3,"",IF(AND(O11=P11,P11=Q11),"3/3",IF(OR(O11=P11,O11=Q11,P11=Q11),"2/3","0/3")))
A12: 11 | B12: W4399911213 | C12: WikiContradict: A Benchmark for Evaluating LLMs on R | D12: accuracy | E12: 86.7 | F12: B | G12: 81.111111 | H12: 76.25 | I12: 86.25 | J12: 240 | K12: 0 | M12: 편차 | X12: =IF(COUNTA(O12:Q12)<3,"",IF(AND(O12=P12,P12=Q12),O12,IF(O12=P12,O12,IF(O12=Q12,O12,IF(P12=Q12,P12,"판정 불능"))))) | Y12: =IF(COUNTA(O12:Q12)<3,"",IF(AND(O12=P12,P12=Q12),"3/3",IF(OR(O12=P12,O12=Q12,P12=Q12),"2/3","0/3")))
A13: 12 | B13: W4399911213 | C13: WikiContradict: A Benchmark for Evaluating LLMs on R | D13: accuracy | E13: 86.7 | F13: C | G13: 86.667 | H13: 82.5 | I13: 90.833 | J13: 240 | K13: 0 | M13: 재현 | X13: =IF(COUNTA(O13:Q13)<3,"",IF(AND(O13=P13,P13=Q13),O13,IF(O13=P13,O13,IF(O13=Q13,O13,IF(P13=Q13,P13,"판정 불능"))))) | Y13: =IF(COUNTA(O13:Q13)<3,"",IF(AND(O13=P13,P13=Q13),"3/3",IF(OR(O13=P13,O13=Q13,P13=Q13),"2/3","0/3")))
A14: 13 | B14: W4399911213 | C14: WikiContradict: A Benchmark for Evaluating LLMs on R | D14: accuracy | E14: 86.7 | F14: D | G14: 85 | H14: 80.833 | I14: 89.583 | J14: 240 | K14: 0 | M14: 재현 | X14: =IF(COUNTA(O14:Q14)<3,"",IF(AND(O14=P14,P14=Q14),O14,IF(O14=P14,O14,IF(O14=Q14,O14,IF(P14=Q14,P14,"판정 불능"))))) | Y14: =IF(COUNTA(O14:Q14)<3,"",IF(AND(O14=P14,P14=Q14),"3/3",IF(OR(O14=P14,O14=Q14,P14=Q14),"2/3","0/3")))
A15: 14 | B15: W4399911213 | C15: WikiContradict: A Benchmark for Evaluating LLMs on R | D15: accuracy | E15: 86.7 | F15: E | G15: 85.47 | H15: 80.769 | I15: 89.744 | J15: 234 | K15: 0 | L15: 예 | M15: 재현 | X15: =IF(COUNTA(O15:Q15)<3,"",IF(AND(O15=P15,P15=Q15),O15,IF(O15=P15,O15,IF(O15=Q15,O15,IF(P15=Q15,P15,"판정 불능"))))) | Y15: =IF(COUNTA(O15:Q15)<3,"",IF(AND(O15=P15,P15=Q15),"3/3",IF(OR(O15=P15,O15=Q15,P15=Q15),"2/3","0/3")))
A16: 15 | B16: W4399911276 | C16: Whiteboard-of-Thought: Thinking Step-by-Step Across | D16: accuracy | E16: 19.6 | F16: A | G16: 20 | H16: 14.8 | I16: 24.4 | J16: 250 | K16: 2 | M16: 재현 | X16: =IF(COUNTA(O16:Q16)<3,"",IF(AND(O16=P16,P16=Q16),O16,IF(O16=P16,O16,IF(O16=Q16,O16,IF(P16=Q16,P16,"판정 불능"))))) | Y16: =IF(COUNTA(O16:Q16)<3,"",IF(AND(O16=P16,P16=Q16),"3/3",IF(OR(O16=P16,O16=Q16,P16=Q16),"2/3","0/3")))
A17: 16 | B17: W4399911276 | C17: Whiteboard-of-Thought: Thinking Step-by-Step Across | D17: accuracy | E17: 19.6 | F17: B | G17: 80 | H17: 75.2 | I17: 84.8 | J17: 250 | K17: 0 | M17: 편차 | X17: =IF(COUNTA(O17:Q17)<3,"",IF(AND(O17=P17,P17=Q17),O17,IF(O17=P17,O17,IF(O17=Q17,O17,IF(P17=Q17,P17,"판정 불능"))))) | Y17: =IF(COUNTA(O17:Q17)<3,"",IF(AND(O17=P17,P17=Q17),"3/3",IF(OR(O17=P17,O17=Q17,P17=Q17),"2/3","0/3")))
A18: 17 | B18: W4399911276 | C18: Whiteboard-of-Thought: Thinking Step-by-Step Across | D18: accuracy | E18: 19.6 | F18: C | G18: 0 | H18: 0 | I18: 0 | J18: 250 | K18: 250 | M18: 확인 필요 | X18: =IF(COUNTA(O18:Q18)<3,"",IF(AND(O18=P18,P18=Q18),O18,IF(O18=P18,O18,IF(O18=Q18,O18,IF(P18=Q18,P18,"판정 불능"))))) | Y18: =IF(COUNTA(O18:Q18)<3,"",IF(AND(O18=P18,P18=Q18),"3/3",IF(OR(O18=P18,O18=Q18,P18=Q18),"2/3","0/3")))
A19: 18 | B19: W4399911276 | C19: Whiteboard-of-Thought: Thinking Step-by-Step Across | D19: accuracy | E19: 19.6 | F19: D | G19: 15.2 | H19: 10.8 | I19: 19.6 | J19: 250 | K19: 0 | M19: 재현 | X19: =IF(COUNTA(O19:Q19)<3,"",IF(AND(O19=P19,P19=Q19),O19,IF(O19=P19,O19,IF(O19=Q19,O19,IF(P19=Q19,P19,"판정 불능"))))) | Y19: =IF(COUNTA(O19:Q19)<3,"",IF(AND(O19=P19,P19=Q19),"3/3",IF(OR(O19=P19,O19=Q19,P19=Q19),"2/3","0/3")))
A20: 19 | B20: W4399911276 | C20: Whiteboard-of-Thought: Thinking Step-by-Step Across | D20: accuracy | E20: 19.6 | F20: E | G20: 69.942 | H20: 63.006 | I20: 76.879 | J20: 173 | K20: 0 | L20: 예 | M20: 편차 | X20: =IF(COUNTA(O20:Q20)<3,"",IF(AND(O20=P20,P20=Q20),O20,IF(O20=P20,O20,IF(O20=Q20,O20,IF(P20=Q20,P20,"판정 불능"))))) | Y20: =IF(COUNTA(O20:Q20)<3,"",IF(AND(O20=P20,P20=Q20),"3/3",IF(OR(O20=P20,O20=Q20,P20=Q20),"2/3","0/3")))
A21: 20 | B21: W4399912745 | C21: ALiiCE: Evaluating Positional Fine-grained Citation | D21: custom | E21: 47 | F21: A | G21: 46.716 | H21: 44.406 | I21: 49.173 | J21: 707 | K21: 0 | L21: 예 | M21: 재현 | X21: =IF(COUNTA(O21:Q21)<3,"",IF(AND(O21=P21,P21=Q21),O21,IF(O21=P21,O21,IF(O21=Q21,O21,IF(P21=Q21,P21,"판정 불능"))))) | Y21: =IF(COUNTA(O21:Q21)<3,"",IF(AND(O21=P21,P21=Q21),"3/3",IF(OR(O21=P21,O21=Q21,P21=Q21),"2/3","0/3")))
A22: 21 | B22: W4399912745 | C22: ALiiCE: Evaluating Positional Fine-grained Citation | D22: custom | E22: 47 | F22: B | G22: 45.583 | H22: 42.88 | I22: 48.202 | J22: 595 | K22: 0 | L22: 예 | M22: 재현 | X22: =IF(COUNTA(O22:Q22)<3,"",IF(AND(O22=P22,P22=Q22),O22,IF(O22=P22,O22,IF(O22=Q22,O22,IF(P22=Q22,P22,"판정 불능"))))) | Y22: =IF(COUNTA(O22:Q22)<3,"",IF(AND(O22=P22,P22=Q22),"3/3",IF(OR(O22=P22,O22=Q22,P22=Q22),"2/3","0/3")))
A23: 22 | B23: W4399912745 | C23: ALiiCE: Evaluating Positional Fine-grained Citation | D23: custom | E23: 47 | F23: C | G23: 47.138 | H23: 45.012 | I23: 49.406 | J23: 948 | K23: 0 | M23: 재현 | X23: =IF(COUNTA(O23:Q23)<3,"",IF(AND(O23=P23,P23=Q23),O23,IF(O23=P23,O23,IF(O23=Q23,O23,IF(P23=Q23,P23,"판정 불능"))))) | Y23: =IF(COUNTA(O23:Q23)<3,"",IF(AND(O23=P23,P23=Q23),"3/3",IF(OR(O23=P23,O23=Q23,P23=Q23),"2/3","0/3")))
A24: 23 | B24: W4399912745 | C24: ALiiCE: Evaluating Positional Fine-grained Citation | D24: custom | E24: 47 | F24: D | G24: 37.598309 | H24: 35.517962 | I24: 39.553795 | J24: 907 | K24: 0 | L24: 예 | M24: 편차 | X24: =IF(COUNTA(O24:Q24)<3,"",IF(AND(O24=P24,P24=Q24),O24,IF(O24=P24,O24,IF(O24=Q24,O24,IF(P24=Q24,P24,"판정 불능"))))) | Y24: =IF(COUNTA(O24:Q24)<3,"",IF(AND(O24=P24,P24=Q24),"3/3",IF(OR(O24=P24,O24=Q24,P24=Q24),"2/3","0/3")))
A25: 24 | B25: W4399912745 | C25: ALiiCE: Evaluating Positional Fine-grained Citation | D25: custom | E25: 47 | F25: E | G25: 49.033 | H25: 46.858 | I25: 51.231 | J25: 948 | K25: 0 | M25: 재현 | X25: =IF(COUNTA(O25:Q25)<3,"",IF(AND(O25=P25,P25=Q25),O25,IF(O25=P25,O25,IF(O25=Q25,O25,IF(P25=Q25,P25,"판정 불능"))))) | Y25: =IF(COUNTA(O25:Q25)<3,"",IF(AND(O25=P25,P25=Q25),"3/3",IF(OR(O25=P25,O25=Q25,P25=Q25),"2/3","0/3")))
A26: 25 | B26: W4400065264 | C26: Following Length Constraints in Instructions | D26: custom | E26: 49.3 | F26: A | G26: 13.092 | H26: 10.723 | I26: 15.461 | J26: 802 | K26: 0 | M26: 편차 | X26: =IF(COUNTA(O26:Q26)<3,"",IF(AND(O26=P26,P26=Q26),O26,IF(O26=P26,O26,IF(O26=Q26,O26,IF(P26=Q26,P26,"판정 불능"))))) | Y26: =IF(COUNTA(O26:Q26)<3,"",IF(AND(O26=P26,P26=Q26),"3/3",IF(OR(O26=P26,O26=Q26,P26=Q26),"2/3","0/3")))
A27: 26 | B27: W4400065264 | C27: Following Length Constraints in Instructions | D27: custom | E27: 49.3 | F27: B | G27: 12.968 | H27: 10.599 | I27: 15.337 | J27: 802 | K27: 0 | M27: 편차 | X27: =IF(COUNTA(O27:Q27)<3,"",IF(AND(O27=P27,P27=Q27),O27,IF(O27=P27,O27,IF(O27=Q27,O27,IF(P27=Q27,P27,"판정 불능"))))) | Y27: =IF(COUNTA(O27:Q27)<3,"",IF(AND(O27=P27,P27=Q27),"3/3",IF(OR(O27=P27,O27=Q27,P27=Q27),"2/3","0/3")))
A28: 27 | B28: W4400065264 | C28: Following Length Constraints in Instructions | D28: custom | E28: 49.3 | F28: C | G28: 53.366584 | H28: 49.875312 | I28: 56.857855 | J28: 802 | K28: 0 | M28: 근접 | X28: =IF(COUNTA(O28:Q28)<3,"",IF(AND(O28=P28,P28=Q28),O28,IF(O28=P28,O28,IF(O28=Q28,O28,IF(P28=Q28,P28,"판정 불능"))))) | Y28: =IF(COUNTA(O28:Q28)<3,"",IF(AND(O28=P28,P28=Q28),"3/3",IF(OR(O28=P28,O28=Q28,P28=Q28),"2/3","0/3")))
A29: 28 | B29: W4400065264 | C29: Following Length Constraints in Instructions | D29: custom | E29: 49.3 | F29: D | G29: 0.623 | H29: 0.125 | I29: 1.247 | J29: 802 | K29: 0 | M29: 편차 | X29: =IF(COUNTA(O29:Q29)<3,"",IF(AND(O29=P29,P29=Q29),O29,IF(O29=P29,O29,IF(O29=Q29,O29,IF(P29=Q29,P29,"판정 불능"))))) | Y29: =IF(COUNTA(O29:Q29)<3,"",IF(AND(O29=P29,P29=Q29),"3/3",IF(OR(O29=P29,O29=Q29,P29=Q29),"2/3","0/3")))
A30: 29 | B30: W4400065264 | C30: Following Length Constraints in Instructions | D30: custom | E30: 49.3 | F30: E | G30: 8.105 | H30: 6.234 | I30: 10.1 | J30: 802 | K30: 0 | M30: 편차 | X30: =IF(COUNTA(O30:Q30)<3,"",IF(AND(O30=P30,P30=Q30),O30,IF(O30=P30,O30,IF(O30=Q30,O30,IF(P30=Q30,P30,"판정 불능"))))) | Y30: =IF(COUNTA(O30:Q30)<3,"",IF(AND(O30=P30,P30=Q30),"3/3",IF(OR(O30=P30,O30=Q30,P30=Q30),"2/3","0/3")))
A31: 30 | B31: W4400375186 | C31: CEB: Compositional Evaluation Benchmark for Fairness | D31: micro_f1 | E31: 69.5 | F31: A | G31: 68 | H31: 61 | I31: 74.5 | J31: 200 | K31: 0 | M31: 재현 | X31: =IF(COUNTA(O31:Q31)<3,"",IF(AND(O31=P31,P31=Q31),O31,IF(O31=P31,O31,IF(O31=Q31,O31,IF(P31=Q31,P31,"판정 불능"))))) | Y31: =IF(COUNTA(O31:Q31)<3,"",IF(AND(O31=P31,P31=Q31),"3/3",IF(OR(O31=P31,O31=Q31,P31=Q31),"2/3","0/3")))
A32: 31 | B32: W4400375186 | C32: CEB: Compositional Evaluation Benchmark for Fairness | D32: micro_f1 | E32: 69.5 | F32: B | G32: 83 | H32: 77.5 | I32: 88.5 | J32: 200 | K32: 0 | M32: 편차 | X32: =IF(COUNTA(O32:Q32)<3,"",IF(AND(O32=P32,P32=Q32),O32,IF(O32=P32,O32,IF(O32=Q32,O32,IF(P32=Q32,P32,"판정 불능"))))) | Y32: =IF(COUNTA(O32:Q32)<3,"",IF(AND(O32=P32,P32=Q32),"3/3",IF(OR(O32=P32,O32=Q32,P32=Q32),"2/3","0/3")))
A33: 32 | B33: W4400375186 | C33: CEB: Compositional Evaluation Benchmark for Fairness | D33: micro_f1 | E33: 69.5 | F33: C | G33: 94.118 | H33: 90.441 | I33: 97.794 | J33: 136 | K33: 0 | L33: 예 | M33: 편차 | X33: =IF(COUNTA(O33:Q33)<3,"",IF(AND(O33=P33,P33=Q33),O33,IF(O33=P33,O33,IF(O33=Q33,O33,IF(P33=Q33,P33,"판정 불능"))))) | Y33: =IF(COUNTA(O33:Q33)<3,"",IF(AND(O33=P33,P33=Q33),"3/3",IF(OR(O33=P33,O33=Q33,P33=Q33),"2/3","0/3")))
A34: 33 | B34: W4400434899 | C34: Are Large Language Models Strategic Decision Makers? | D34: accuracy | E34: 25.5 | F34: A | G34: 26.208333 | H34: 23.5 | I34: 29.375 | J34: 800 | K34: 0 | M34: 재현 | X34: =IF(COUNTA(O34:Q34)<3,"",IF(AND(O34=P34,P34=Q34),O34,IF(O34=P34,O34,IF(O34=Q34,O34,IF(P34=Q34,P34,"판정 불능"))))) | Y34: =IF(COUNTA(O34:Q34)<3,"",IF(AND(O34=P34,P34=Q34),"3/3",IF(OR(O34=P34,O34=Q34,P34=Q34),"2/3","0/3")))
A35: 34 | B35: W4400434899 | C35: Are Large Language Models Strategic Decision Makers? | D35: accuracy | E35: 25.5 | F35: B | G35: 37.856 | H35: 34.328 | I35: 41.52 | J35: 737 | K35: 0 | L35: 예 | M35: 편차 | X35: =IF(COUNTA(O35:Q35)<3,"",IF(AND(O35=P35,P35=Q35),O35,IF(O35=P35,O35,IF(O35=Q35,O35,IF(P35=Q35,P35,"판정 불능"))))) | Y35: =IF(COUNTA(O35:Q35)<3,"",IF(AND(O35=P35,P35=Q35),"3/3",IF(OR(O35=P35,O35=Q35,P35=Q35),"2/3","0/3")))
A36: 35 | B36: W4400434899 | C36: Are Large Language Models Strategic Decision Makers? | D36: accuracy | E36: 25.5 | F36: C | G36: 50 | H36: 46.5 | I36: 53.625 | J36: 800 | K36: 0 | M36: 편차 | X36: =IF(COUNTA(O36:Q36)<3,"",IF(AND(O36=P36,P36=Q36),O36,IF(O36=P36,O36,IF(O36=Q36,O36,IF(P36=Q36,P36,"판정 불능"))))) | Y36: =IF(COUNTA(O36:Q36)<3,"",IF(AND(O36=P36,P36=Q36),"3/3",IF(OR(O36=P36,O36=Q36,P36=Q36),"2/3","0/3")))
A37: 36 | B37: W4400434899 | C37: Are Large Language Models Strategic Decision Makers? | D37: accuracy | E37: 25.5 | F37: D | G37: 50.552 | H37: 46.958 | I37: 54.282 | J37: 724 | K37: 0 | L37: 예 | M37: 편차 | X37: =IF(COUNTA(O37:Q37)<3,"",IF(AND(O37=P37,P37=Q37),O37,IF(O37=P37,O37,IF(O37=Q37,O37,IF(P37=Q37,P37,"판정 불능"))))) | Y37: =IF(COUNTA(O37:Q37)<3,"",IF(AND(O37=P37,P37=Q37),"3/3",IF(OR(O37=P37,O37=Q37,P37=Q37),"2/3","0/3")))
A38: 37 | B38: W4400434899 | C38: Are Large Language Models Strategic Decision Makers? | D38: accuracy | E38: 25.5 | F38: E | G38: 50 | H38: 46.625 | I38: 53.25 | J38: 800 | K38: 0 | M38: 편차 | X38: =IF(COUNTA(O38:Q38)<3,"",IF(AND(O38=P38,P38=Q38),O38,IF(O38=P38,O38,IF(O38=Q38,O38,IF(P38=Q38,P38,"판정 불능"))))) | Y38: =IF(COUNTA(O38:Q38)<3,"",IF(AND(O38=P38,P38=Q38),"3/3",IF(OR(O38=P38,O38=Q38,P38=Q38),"2/3","0/3")))
A39: 38 | B39: W4400611869 | C39: Lynx: An Open Source Hallucination Evaluation Model | D39: accuracy | E39: 82.2 | F39: A | G39: 88.283 | H39: 86.361 | I39: 90.303 | J39: 990 | K39: 1 | L39: 예 | M39: 편차 | X39: =IF(COUNTA(O39:Q39)<3,"",IF(AND(O39=P39,P39=Q39),O39,IF(O39=P39,O39,IF(O39=Q39,O39,IF(P39=Q39,P39,"판정 불능"))))) | Y39: =IF(COUNTA(O39:Q39)<3,"",IF(AND(O39=P39,P39=Q39),"3/3",IF(OR(O39=P39,O39=Q39,P39=Q39),"2/3","0/3")))
A40: 39 | B40: W4400611869 | C40: Lynx: An Open Source Hallucination Evaluation Model | D40: accuracy | E40: 82.2 | F40: B | G40: 90.784 | H40: 88.431 | I40: 93.333 | J40: 510 | K40: 0 | L40: 예 | M40: 편차 | X40: =IF(COUNTA(O40:Q40)<3,"",IF(AND(O40=P40,P40=Q40),O40,IF(O40=P40,O40,IF(O40=Q40,O40,IF(P40=Q40,P40,"판정 불능"))))) | Y40: =IF(COUNTA(O40:Q40)<3,"",IF(AND(O40=P40,P40=Q40),"3/3",IF(OR(O40=P40,O40=Q40,P40=Q40),"2/3","0/3")))
...

Sheet 요약
A1: 집계 (수식) | B1: TierA_claims | C1: PromptLevel_blind
A2: 코딩된 행 수 (세 명 모두) | B2: =COUNTIF(TierA_claims!W2:W96,"<>") | C2: =COUNTIF(PromptLevel_blind!X2:X344,"<>")
A3: 다수결 생존 | B3: =COUNTIF(TierA_claims!W2:W96,"생존") | C3: =COUNTIF(PromptLevel_blind!X2:X344,"생존")
A4: 다수결 부분 생존 | B4: =COUNTIF(TierA_claims!W2:W96,"부분 생존") | C4: =COUNTIF(PromptLevel_blind!X2:X344,"부분 생존")
A5: 다수결 사망 | B5: =COUNTIF(TierA_claims!W2:W96,"사망") | C5: =COUNTIF(PromptLevel_blind!X2:X344,"사망")
A6: 다수결 판정 불능 | B6: =COUNTIF(TierA_claims!W2:W96,"판정 불능") | C6: =COUNTIF(PromptLevel_blind!X2:X344,"판정 불능")
A7: 3/3 일치 | B7: =COUNTIF(TierA_claims!X2:X96,"3/3") | C7: =COUNTIF(PromptLevel_blind!Y2:Y344,"3/3")
A8: 2/3 일치 | B8: =COUNTIF(TierA_claims!X2:X96,"2/3") | C8: =COUNTIF(PromptLevel_blind!Y2:Y344,"2/3")
A9: 0/3 일치 | B9: =COUNTIF(TierA_claims!X2:X96,"0/3") | C9: =COUNTIF(PromptLevel_blind!Y2:Y344,"0/3")
A11: 세 판정자의 파일을 합치고 자동 가안과 교차표를 만드는 것은 scripts/judgment_merge.py다. 위 수식은 채워진 행만 센다.
